<?xml version="1.0"?>
<robot xmlns:xacro="http://www.ros.org/wiki/ric" name="komodo_$(arg komodo_id)_ric_description">
  <link
    name="komodo_$(arg komodo_id)_base_link">
    <inertial>
      <origin
        xyz="-0.0202567965431546 4.50159006641306E-05 0.00729101578040162"
        rpy="0 0 0" />
      <mass
        value="4.55152626896128" />
      <inertia
        ixx="0.0740906721192151"
        ixy="-4.69051392523534E-05"
        ixz="-0.00876481206959482"
        iyy="0.139330290469501"
        iyz="1.19836169980014E-05"
        izz="0.197305459998082" />
    </inertial>
    <visual>
      <origin
        xyz="0 0 0"
        rpy="0 0 0" />
      <geometry>
        <mesh
          filename="package://ric_description/komodo/meshes_elevator/base_link.STL" />
      </geometry>
      <material
        name="">
        <color
          rgba="0.52941176470588 0.52941176470588 0.52941176470588 1" />
      </material>
    </visual>
    <collision>
      <origin
        xyz="0 0 0"
        rpy="0 0 0" />
      <geometry>
        <mesh
          filename="package://ric_description/komodo/meshes_elevator/base_link.STL" />
      </geometry>
    </collision>
  </link>
  <link
    name="komodo_$(arg komodo_id)_FR_Wheel_link">
    <inertial>
      <origin
        xyz="-0.00125662336313273 1.11355998344831E-05 1.03716608161431E-05"
        rpy="0 0 0" />
      <mass
        value="3.8342746769566" />
      <inertia
        ixx="0.0296525477119636"
        ixy="2.79965420060088E-06"
        ixz="2.53736550213318E-08"
        iyy="0.016371794067571"
        iyz="8.36492278178838E-07"
        izz="0.0163752042696063" />
    </inertial>
    <visual>
      <origin
        xyz="0 0 0"
        rpy="0 0 0" />
      <geometry>
        <mesh
          filename="package://ric_description/komodo/meshes_elevator/FR_Wheel_link.STL" />
      </geometry>
      <material
        name="">
        <color
          rgba="0.15 0.15 0.15 1" />
      </material>
    </visual>
    <collision>
      <origin
        xyz="0 0 0"
        rpy="0 0 0" />
      <geometry>
        <mesh
          filename="package://ric_description/komodo/meshes_elevator/FR_Wheel_link.STL" />
      </geometry>
    </collision>
  </link>
  <joint
    name="komodo_$(arg komodo_id)_FR_Wheel_joint"
    type="continuous">
    <origin
      xyz="0.173999999999995 -0.2009 0"
      rpy="0 2.91353065389309E-16 -1.5707963267949" />
    <parent
      link="komodo_$(arg komodo_id)_base_link" />
    <child
      link="komodo_$(arg komodo_id)_FR_Wheel_link" />
    <axis
      xyz="-1 0 0" />
  </joint>
  <link
    name="komodo_$(arg komodo_id)_FL_Wheel_link">
    <inertial>
      <origin
        xyz="-0.00125662485896622 1.49949992671872E-05 2.59231426950774E-06"
        rpy="0 0 0" />
      <mass
        value="3.83427522711725" />
      <inertia
        ixx="0.0296525525949412"
        ixy="2.35764759365733E-06"
        ixz="-1.51000746821569E-06"
        iyy="0.0163720506962301"
        iyz="-1.22544016689733E-06"
        izz="0.0163749526296554" />
    </inertial>
    <visual>
      <origin
        xyz="0 0 0"
        rpy="0 0 0" />
      <geometry>
        <mesh
          filename="package://ric_description/komodo/meshes_elevator/FL_Wheel_link.STL" />
      </geometry>
      <material
        name="">
        <color
          rgba="0.15 0.15 0.15 1" />
      </material>
    </visual>
    <collision>
      <origin
        xyz="0 0 0"
        rpy="0 0 0" />
      <geometry>
        <mesh
          filename="package://ric_description/komodo/meshes_elevator/FL_Wheel_link.STL" />
      </geometry>
    </collision>
  </link>
  <joint
    name="komodo_$(arg komodo_id)_FL_Wheel_joint"
    type="continuous">
    <origin
      xyz="0.173999999999995 0.2009 0"
      rpy="0 -1.52736144460753E-16 1.5707963267949" />
    <parent
      link="komodo_$(arg komodo_id)_base_link" />
    <child
      link="komodo_$(arg komodo_id)_FL_Wheel_link" />
    <axis
      xyz="1 0 0" />
  </joint>
  <link
    name="komodo_$(arg komodo_id)_RR_Wheel_link">
    <inertial>
      <origin
        xyz="-0.00125662335525084 1.11355843264715E-05 1.03716365456246E-05"
        rpy="0 0 0" />
      <mass
        value="3.8342746798544" />
      <inertia
        ixx="0.0296525477478165"
        ixy="2.79965101407256E-06"
        ixz="2.53705788024761E-08"
        iyy="0.0163717940952031"
        iyz="8.36482056178988E-07"
        izz="0.016375204276916" />
    </inertial>
    <visual>
      <origin
        xyz="0 0 0"
        rpy="0 0 0" />
      <geometry>
        <mesh
          filename="package://ric_description/komodo/meshes_elevator/RR_Wheel_link.STL" />
      </geometry>
      <material
        name="">
        <color
          rgba="0.15 0.15 0.15 1" />
      </material>
    </visual>
    <collision>
      <origin
        xyz="0 0 0"
        rpy="0 0 0" />
      <geometry>
        <mesh
          filename="package://ric_description/komodo/meshes_elevator/RR_Wheel_link.STL" />
      </geometry>
    </collision>
  </link>
  <joint
    name="komodo_$(arg komodo_id)_RR_Wheel_joint"
    type="continuous">
    <origin
      xyz="-0.156000000000005 -0.2009 0"
      rpy="0 2.91353065389309E-16 -1.5707963267949" />
    <parent
      link="komodo_$(arg komodo_id)_base_link" />
    <child
      link="komodo_$(arg komodo_id)_RR_Wheel_link" />
    <axis
      xyz="-1 0 0" />
  </joint>
  <link
    name="komodo_$(arg komodo_id)_RL_Wheel_link">
    <inertial>
      <origin
        xyz="-0.00125662481023878 1.51826398065158E-05 -1.03148726989222E-06"
        rpy="0 0 0" />
      <mass
        value="3.83427523202811" />
      <inertia
        ixx="0.029652552601883"
        ixy="1.93315051135156E-06"
        ixz="-2.02525824996084E-06"
        iyy="0.0163727771181788"
        iyz="-1.7555864073833E-06"
        izz="0.0163742262291497" />
    </inertial>
    <visual>
      <origin
        xyz="0 0 0"
        rpy="0 0 0" />
      <geometry>
        <mesh
          filename="package://ric_description/komodo/meshes_elevator/RL_Wheel_link.STL" />
      </geometry>
      <material
        name="">
        <color
          rgba="0.15 0.15 0.15 1" />
      </material>
    </visual>
    <collision>
      <origin
        xyz="0 0 0"
        rpy="0 0 0" />
      <geometry>
        <mesh
          filename="package://ric_description/komodo/meshes_elevator/RL_Wheel_link.STL" />
      </geometry>
    </collision>
  </link>
  <joint
    name="komodo_$(arg komodo_id)_RL_Wheel_joint"
    type="continuous">
    <origin
      xyz="-0.156000000000005 0.2009 0"
      rpy="0 -1.52736144460753E-16 1.5707963267949" />
    <parent
      link="komodo_$(arg komodo_id)_base_link" />
    <child
      link="komodo_$(arg komodo_id)_RL_Wheel_link" />
    <axis
      xyz="1 0 0" />
  </joint>
  <link
    name="komodo_$(arg komodo_id)_Left_URF_link">
    <inertial>
      <origin
        xyz="-0.00942258060477766 -6.76888278501216E-05 0.000193183712129563"
        rpy="0 0 0" />
      <mass
        value="0.00277487854391406" />
      <inertia
        ixx="1.28314681514112E-07"
        ixy="1.54585356342761E-10"
        ixz="-3.11030599725547E-09"
        iyy="1.1894067250004E-07"
        iyz="4.35265830364911E-09"
        izz="1.28434121553123E-07" />
    </inertial>
    <visual>
      <origin
        xyz="0 0 0"
        rpy="0 0 0" />
      <geometry>
        <mesh
          filename="package://ric_description/komodo/meshes_elevator/Left_URF_link.STL" />
      </geometry>
      <material
        name="">
        <color
          rgba="0.1 0.1 0.1 1" />
      </material>
    </visual>
    <collision>
      <origin
        xyz="0 0 0"
        rpy="0 0 0" />
      <geometry>
        <mesh
          filename="package://ric_description/komodo/meshes_elevator/Left_URF_link.STL" />
      </geometry>
    </collision>
  </link>
  <joint
    name="komodo_$(arg komodo_id)_Left_URF_joint"
    type="fixed">
    <origin
      xyz="-0.0223641326154781 0.137250000000005 0.138508176066688"
      rpy="0 -1.52736144460753E-16 1.5707963267949" />
    <parent
      link="komodo_$(arg komodo_id)_base_link" />
    <child
      link="komodo_$(arg komodo_id)_Left_URF_link" />
    <axis
      xyz="0 0 0" />
  </joint>
  <link
    name="komodo_$(arg komodo_id)_Rear_URF_link">
    <inertial>
      <origin
        xyz="-0.00942258060476636 -6.76888278372571E-05 0.000193183712129591"
        rpy="0 0 0" />
      <mass
        value="0.00277487854391407" />
      <inertia
        ixx="1.28314681514114E-07"
        ixy="1.5458535634316E-10"
        ixz="-3.11030599725607E-09"
        iyy="1.18940672500041E-07"
        iyz="4.35265830364843E-09"
        izz="1.28434121553124E-07" />
    </inertial>
    <visual>
      <origin
        xyz="0 0 0"
        rpy="0 0 0" />
      <geometry>
        <mesh
          filename="package://ric_description/komodo/meshes_elevator/Rear_URF_link.STL" />
      </geometry>
      <material
        name="">
        <color
          rgba="0.1 0.1 0.1 1" />
      </material>
    </visual>
    <collision>
      <origin
        xyz="0 0 0"
        rpy="0 0 0" />
      <geometry>
        <mesh
          filename="package://ric_description/komodo/meshes_elevator/Rear_URF_link.STL" />
      </geometry>
    </collision>
  </link>
  <joint
    name="komodo_$(arg komodo_id)_Rear_URF_joint"
    type="fixed">
    <origin
      xyz="-0.267499972183238 -5.07999999948743E-05 0.108"
      rpy="-2.22044604925031E-16 0 3.14159265358979" />
    <parent
      link="komodo_$(arg komodo_id)_base_link" />
    <child
      link="komodo_$(arg komodo_id)_Rear_URF_link" />
    <axis
      xyz="0 0 0" />
  </joint>
  <link
    name="komodo_$(arg komodo_id)_Right_URF_link">
    <inertial>
      <origin
        xyz="-0.00942258060475351 -6.76888278484597E-05 0.000193183712129535"
        rpy="0 0 0" />
      <mass
        value="0.00277487854391411" />
      <inertia
        ixx="1.28314681514116E-07"
        ixy="1.5458535634248E-10"
        ixz="-3.11030599725546E-09"
        iyy="1.18940672500042E-07"
        iyz="4.3526583036491E-09"
        izz="1.28434121553126E-07" />
    </inertial>
    <visual>
      <origin
        xyz="0 0 0"
        rpy="0 0 0" />
      <geometry>
        <mesh
          filename="package://ric_description/komodo/meshes_elevator/Right_URF_link.STL" />
      </geometry>
      <material
        name="">
        <color
          rgba="0.1 0.1 0.1 1" />
      </material>
    </visual>
    <collision>
      <origin
        xyz="0 0 0"
        rpy="0 0 0" />
      <geometry>
        <mesh
          filename="package://ric_description/komodo/meshes_elevator/Right_URF_link.STL" />
      </geometry>
    </collision>
  </link>
  <joint
    name="komodo_$(arg komodo_id)_Right_URF_joint"
    type="fixed">
    <origin
      xyz="-0.0222625326154781 -0.137249999999995 0.138508176066688"
      rpy="0 2.91353065389309E-16 -1.5707963267949" />
    <parent
      link="komodo_$(arg komodo_id)_base_link" />
    <child
      link="komodo_$(arg komodo_id)_Right_URF_link" />
    <axis
      xyz="0 0 0" />
  </joint>
  <link
    name="komodo_$(arg komodo_id)_Front_Camera_link">
    <inertial>
      <origin
        xyz="3.63553471587064E-06 0.000213443852909057 -0.00979905092954425"
        rpy="0 0 0" />
      <mass
        value="0.0346828331927877" />
      <inertia
        ixx="6.28790547336205E-06"
        ixy="-2.06834494928096E-09"
        ixz="1.17994816104851E-09"
        iyy="6.08020816375924E-06"
        iyz="3.61787794067541E-08"
        izz="9.95214453956247E-06" />
    </inertial>
    <visual>
      <origin
        xyz="0 0 0"
        rpy="0 0 0" />
      <geometry>
        <mesh
          filename="package://ric_description/komodo/meshes_elevator/Front_Camera_link.STL" />
      </geometry>
      <material
        name="">
        <color
          rgba="0.1 0.1 0.1 1" />
      </material>
    </visual>
    <collision>
      <origin
        xyz="0 0 0"
        rpy="0 0 0" />
      <geometry>
        <mesh
          filename="package://ric_description/komodo/meshes_elevator/Front_Camera_link.STL" />
      </geometry>
    </collision>
  </link>
  <joint
    name="komodo_$(arg komodo_id)_Frotn_Camera_joint"
    type="fixed">
    <origin
      xyz="0.262250027816762 0.0875000000000051 0.1"
      rpy="-1.5707963267949 2.91353065389309E-16 -1.5707963267949" />
    <parent
      link="komodo_$(arg komodo_id)_base_link" />
    <child
      link="komodo_$(arg komodo_id)_Front_Camera_link" />
    <axis
      xyz="0 0 0" />
  </joint>
  <link
    name="komodo_$(arg komodo_id)_Laser_link">
    <inertial>
      <origin
        xyz="-5.67786090349132E-05 6.35639788812009E-05 -0.0320034700075499"
        rpy="0 0 0" />
      <mass
        value="0.133672626323352" />
      <inertia
        ixx="7.01753800311364E-05"
        ixy="-5.24162580338929E-08"
        ixz="-1.64205975504515E-07"
        iyy="7.04769388586209E-05"
        iyz="-1.92324838956094E-07"
        izz="4.61464878783426E-05" />
    </inertial>
    <visual>
      <origin
        xyz="0 0 0"
        rpy="0 0 0" />
      <geometry>
        <mesh
          filename="package://ric_description/komodo/meshes_elevator/Laser_link.STL" />
      </geometry>
      <material
        name="">
        <color
          rgba="0.192156862745098 0.1819607843137255 0.1933333333333333 1" />
      </material>
    </visual>
    <collision>
      <origin
        xyz="0 0 0"
        rpy="0 0 0" />
      <geometry>
        <mesh
          filename="package://ric_description/komodo/meshes_elevator/Laser_link.STL" />
      </geometry>
    </collision>
  </link>
  <joint
    name="komodo_$(arg komodo_id)_Laser_joint"
    type="fixed">
    <origin
      xyz="0.234263427816762 0 0.145827195177236"
      rpy="0 0 0" />
    <parent
      link="komodo_$(arg komodo_id)_base_link" />
    <child
      link="komodo_$(arg komodo_id)_Laser_link" />
    <axis
      xyz="0 0 0" />
  </joint>
  <link
    name="komodo_$(arg komodo_id)_Arm_base_link">
    <inertial>
      <origin
        xyz="0.0787832367713514 1.63894955207658E-05 0.30372182598738"
        rpy="0 0 0" />
      <mass
        value="5.82785061945851" />
      <inertia
        ixx="0.262040399352781"
        ixy="-1.20613586206922E-05"
        ixz="0.0219696026578"
        iyy="0.271705564666912"
        iyz="3.10612186063073E-05"
        izz="0.0337682852586326" />
    </inertial>
    <visual>
      <origin
        xyz="0 0 0"
        rpy="0 0 0" />
      <geometry>
        <mesh
          filename="package://ric_description/komodo/meshes_elevator/Arm_base_link.STL" />
      </geometry>
      <material
        name="">
        <color
          rgba="0.4 0.4 0.4 1" />
      </material>
    </visual>
    <collision>
      <origin
        xyz="0 0 0"
        rpy="0 0 0" />
      <geometry>
        <mesh
          filename="package://ric_description/komodo/meshes_elevator/Arm_base_link.STL" />
      </geometry>
    </collision>
  </link>
  <joint
    name="komodo_$(arg komodo_id)_Arm_base_joint"
    type="fixed">
    <origin
      xyz="-0.112249972183238 0 0.167160698455407"
      rpy="0 0 0" />
    <parent
      link="komodo_$(arg komodo_id)_base_link" />
    <child
      link="komodo_$(arg komodo_id)_Arm_base_link" />
    <axis
      xyz="0 0 0" />
  </joint>
  <link
    name="komodo_$(arg komodo_id)_elevator_link">
    <inertial>
      <origin
        xyz="0.0954671716579415 1.91586249009607E-06 -0.0185743175743276"
        rpy="0 0 0" />
      <mass
        value="1.09057945344451" />
      <inertia
        ixx="0.000835857275985966"
        ixy="5.81870910353681E-08"
        ixz="-3.13493979506258E-05"
        iyy="0.00128840659932805"
        iyz="1.45397132642805E-07"
        izz="0.00136461371089342" />
    </inertial>
    <visual>
      <origin
        xyz="0 0 0"
        rpy="0 0 0" />
      <geometry>
        <mesh
          filename="package://ric_description/komodo/meshes_elevator/elevator_link.STL" />
      </geometry>
      <material
        name="">
        <color
          rgba="0.35 0.35 0.35 1" />
      </material>
    </visual>
    <collision>
      <origin
        xyz="0 0 0"
        rpy="0 0 0" />
      <geometry>
        <mesh
          filename="package://ric_description/komodo/meshes_elevator/elevator_link.STL" />
      </geometry>
    </collision>
  </link>
  <joint
    name="komodo_$(arg komodo_id)_elevator_joint"
    type="prismatic">
    <origin
      xyz="0.101457996026178 0 0.0740000000000002"
      rpy="0 0 0" />
    <parent
      link="komodo_$(arg komodo_id)_Arm_base_link" />
    <child
      link="komodo_$(arg komodo_id)_elevator_link" />
    <axis
      xyz="0 0 1" />
   <limit
	lower="0"
	upper="0.45"
	effort="0"
	velocity="0" />
  </joint>
  <link
    name="komodo_$(arg komodo_id)_base_rotation_link">
    <inertial>
      <origin
        xyz="-6.93889390390723E-17 1.46538271444029E-17 0.0623331826247039"
        rpy="0 0 0" />
      <mass
        value="1.52333362223354" />
      <inertia
        ixx="0.00192061019876875"
        ixy="-8.39923257698839E-08"
        ixz="-6.07471919518397E-19"
        iyy="0.000888601580387061"
        iyz="-5.09938803674351E-19"
        izz="0.001306201114282" />
    </inertial>
    <visual>
      <origin
        xyz="0 0 0"
        rpy="0 0 0" />
      <geometry>
        <mesh
          filename="package://ric_description/komodo/meshes_elevator/base_rotation_link.STL" />
      </geometry>
      <material
        name="">
        <color
          rgba="0.3 0.3 0.3 1" />
      </material>
    </visual>
    <collision>
      <origin
        xyz="0 0 0"
        rpy="0 0 0" />
      <geometry>
        <mesh
          filename="package://ric_description/komodo/meshes_elevator/base_rotation_link.STL" />
      </geometry>
    </collision>
  </link>
  <joint
    name="komodo_$(arg komodo_id)_base_rotation_joint"
    type="revolute">
    <origin
      xyz="0.113 0 -0.00400000000000003"
      rpy="0 0 0" />
    <parent
      link="komodo_$(arg komodo_id)_elevator_link" />
    <child
      link="komodo_$(arg komodo_id)_base_rotation_link" />
    <axis
      xyz="0 0 1" />
	 <limit
	lower="-1.57079"
	upper="1.57079"
	effort="0"
	velocity="0" />
  </joint>
  <link
    name="komodo_$(arg komodo_id)_shoulder_link">
    <inertial>
      <origin
        xyz="-4.66247777455853E-06 -9.82289263772941E-05 0.0772888499398813"
        rpy="0 0 0" />
      <mass
        value="0.191480824435982" />
      <inertia
        ixx="0.00107301595767426"
        ixy="-2.97890564117552E-07"
        ixz="-2.01214952294279E-08"
        iyy="0.000975953126734079"
        iyz="-1.1960192138697E-06"
        izz="0.000217659790404293" />
    </inertial>
    <visual>
      <origin
        xyz="0 0 0"
        rpy="0 0 0" />
      <geometry>
        <mesh
          filename="package://ric_description/komodo/meshes_elevator/shoulder_link.STL" />
      </geometry>
      <material
        name="">
        <color
          rgba="0.4 0.4 0.4 1" />
      </material>
    </visual>
    <collision>
      <origin
        xyz="0 0 0"
        rpy="0 0 0" />
      <geometry>
        <mesh
          filename="package://ric_description/komodo/meshes_elevator/shoulder_link.STL" />
      </geometry>
    </collision>
  </link>
  <joint
    name="komodo_$(arg komodo_id)_shoulder_joint"
    type="revolute">
    <origin
      xyz="0 0 0.0835"
      rpy="0 0 0" />
    <parent
      link="komodo_$(arg komodo_id)_base_rotation_link" />
    <child
      link="komodo_$(arg komodo_id)_shoulder_link" />
    <axis
      xyz="0 1 0" />
   <limit
	lower="0"
	upper="1.692969"
	effort="0"
	velocity="0" />
  </joint>
  <link
    name="komodo_$(arg komodo_id)_elbow1_link">
    <inertial>
      <origin
        xyz="3.38829306132937E-05 2.66620552362602E-06 0.0239321015118659"
        rpy="0 0 0" />
      <mass
        value="0.759959108482768" />
      <inertia
        ixx="0.00111562545185235"
        ixy="3.16190978299692E-07"
        ixz="2.8926774836368E-06"
        iyy="0.00114606033599678"
        iyz="-8.11916889616619E-08"
        izz="0.000237163436712144" />
    </inertial>
    <visual>
      <origin
        xyz="0 0 0"
        rpy="0 0 0" />
      <geometry>
        <mesh
          filename="package://ric_description/komodo/meshes_elevator/elbow1_link.STL" />
      </geometry>
      <material
        name="">
        <color
          rgba="0.3 0.3 0.3 1" />
      </material>
    </visual>
    <collision>
      <origin
        xyz="0 0 0"
        rpy="0 0 0" />
      <geometry>
        <mesh
          filename="package://ric_description/komodo/meshes_elevator/elbow1_link.STL" />
      </geometry>
    </collision>
  </link>
  <joint
    name="komodo_$(arg komodo_id)_elbow1_joint"
    type="revolute">
    <origin
      xyz="0 -0.000251155668931501 0.266305434894181"
      rpy="0 0 0" />
    <parent
      link="komodo_$(arg komodo_id)_shoulder_link" />
    <child
      link="komodo_$(arg komodo_id)_elbow1_link" />
    <axis
      xyz="-1 0 0" />
   <limit
	lower="-2.4434"
	upper="2.4434"
	effort="0"
	velocity="0" />
  </joint>
   <link
    name="komodo_$(arg komodo_id)_elbow2_link">
    <inertial>
      <origin
        xyz="0.000512284668490459 -2.29084833272284E-05 0.0885118785637893"
        rpy="0 0 0" />
      <mass
        value="1.12138856829227" />
      <inertia
        ixx="0.0110437300677022"
        ixy="-3.04258914498172E-07"
        ixz="7.91667404759185E-05"
        iyy="0.0110599202123036"
        iyz="-1.2246825546657E-06"
        izz="0.000331598440084596" />
    </inertial>
    <visual>
      <origin
        xyz="0 0 0"
        rpy="0 0 0" />
      <geometry>
        <mesh
          filename="package://ric_description/komodo/meshes_elevator/elbow2_link.STL" />
      </geometry>
      <material
        name="">
        <color
          rgba="0.4 0.4 0.4 1" />
      </material>
    </visual>
    <collision>
      <origin
        xyz="0 0 0"
        rpy="0 0 0" />
      <geometry>
        <mesh
          filename="package://ric_description/komodo/meshes_elevator/elbow2_link.STL" />
      </geometry>
    </collision>
  </link>
  <joint
    name="komodo_$(arg komodo_id)_elbow2_joint"
    type="revolute">
    <origin
      xyz="0 0 0.22399999999847"
      rpy="0 0 0" />
    <parent
      link="komodo_$(arg komodo_id)_elbow1_link" />
    <child
      link="komodo_$(arg komodo_id)_elbow2_link" />
    <axis
      xyz="0 1 0" />
    <limit
	lower="-2.4434"
	upper="2.4434"
	effort="0"
	velocity="0" />
  </joint>
  <link
    name="komodo_$(arg komodo_id)_wrist_link">
    <inertial>
      <origin
        xyz="0.0303673809619356 4.00707611352118E-10 0.000140374211043737"
        rpy="0 0 0" />
      <mass
        value="0.717337417215465" />
      <inertia
        ixx="0.000437528795624211"
        ixy="2.79334685089828E-12"
        ixz="3.9184388902034E-06"
        iyy="0.000211170064630335"
        iyz="-4.20757370549832E-12"
        izz="0.000486392340366095" />
    </inertial>
    <visual>
      <origin
        xyz="0 0 0"
        rpy="0 1.57079632679 0" />
      <geometry>
        <mesh
          filename="package://ric_description/komodo/meshes_elevator/wrist_link.STL" />
      </geometry>
      <material
        name="">
        <color
          rgba="0.3 0.3 0.3 1" />
      </material>
    </visual>
    <collision>
      <origin
        xyz="0 0 0"
        rpy="0 0 0" />
      <geometry>
        <mesh
          filename="package://ric_description/komodo/meshes_elevator/wrist_link.STL" />
      </geometry>
    </collision>
  </link>
  <joint
    name="komodo_$(arg komodo_id)_wrist_joint"
    type="revolute">
    <origin
      xyz="0.0131002732116043 0 0.244749985376465"
      rpy="-7.54547010806299E-10 -1.57079521049999 7.54547010806769E-10" />
    <parent
      link="komodo_$(arg komodo_id)_elbow2_link" />
    <child
      link="komodo_$(arg komodo_id)_wrist_link" />
    <axis
      xyz="1 0 0" />
   <limit
	lower="-1.91986"
	upper="1.91986"
	effort="0"
	velocity="0" />
  </joint>
  <link
    name="komodo_$(arg komodo_id)_left_finger_link">
    <inertial>
      <origin
        xyz="3.72403910764429E-08 0.0148725895621533 0.0333609018907974"
        rpy="0 0 0" />
      <mass
        value="0.0111981711598486" />
      <inertia
        ixx="9.77349829712473E-06"
        ixy="8.75184006227289E-13"
        ixz="7.17229539862538E-12"
        iyy="1.16654058802351E-05"
        iyz="7.84012367212596E-07"
        izz="3.34837133468138E-06" />
    </inertial>
    <visual>
      <origin
        xyz="0 0 0"
        rpy="0 0 0" />
      <geometry>
        <mesh
          filename="package://ric_description/komodo/meshes_elevator/left_finger_link.STL" />
      </geometry>
      <material
        name="">
        <color
          rgba="0.4 0.4 0.4 1" />
      </material>
    </visual>
    <collision>
      <origin
        xyz="0 0 0"
        rpy="0 0 0" />
      <geometry>
        <mesh
          filename="package://ric_description/komodo/meshes_elevator/left_finger_link.STL" />
      </geometry>
    </collision>
  </link>
  <joint
    name="komodo_$(arg komodo_id)_left_finger_joint"
    type="revolute">
    <origin
      xyz="0.0422500000000001 0.0209999999999993 0"
      rpy="-1.68486099328966E-31 1.57079521049999 -8.42292155533488E-16" />
    <parent
      link="komodo_$(arg komodo_id)_wrist_link" />
    <child
      link="komodo_$(arg komodo_id)_left_finger_link" />
    <axis
      xyz="1 0 0" />
   <limit
	lower="-0.87266"
	upper="0.87266"
	effort="0"
	velocity="0" />
  </joint>
  <link
    name="komodo_$(arg komodo_id)_right_finger_link">
    <inertial>
      <origin
        xyz="3.72403914095099E-08 -0.0148725895621533 0.0333609018907972"
        rpy="0 0 0" />
      <mass
        value="0.0111981711598486" />
      <inertia
        ixx="9.77349829712477E-06"
        ixy="-8.75183976470699E-13"
        ixz="7.17229533033965E-12"
        iyy="1.16654058802351E-05"
        iyz="-7.84012367212632E-07"
        izz="3.34837133468142E-06" />
    </inertial>
    <visual>
      <origin
        xyz="0 0 0"
        rpy="0 0 0" />
      <geometry>
        <mesh
          filename="package://ric_description/komodo/meshes_elevator/right_finger_link.STL" />
      </geometry>
      <material
        name="">
        <color
          rgba="0.4 0.4 0.4 1" />
      </material>
    </visual>
    <collision>
      <origin
        xyz="0 0 0"
        rpy="0 0 0" />
      <geometry>
        <mesh
          filename="package://ric_description/komodo/meshes_elevator/right_finger_link.STL" />
      </geometry>
    </collision>
  </link>
  <joint
    name="komodo_$(arg komodo_id)_right_finger_joint"
    type="revolute">
    <origin
      xyz="0.0422499999999997 -0.0210000000000011 0"
      rpy="-1.68486099328966E-31 1.57079521049999 -8.42292155533488E-16" />
    <parent
      link="komodo_$(arg komodo_id)_wrist_link" />
    <child
      link="komodo_$(arg komodo_id)_right_finger_link" />
    <axis
      xyz="1 0 0" />
   <limit
	lower="-0.87266"
	upper="0.87266"
	effort="0"
	velocity="0" />
  </joint>
  <link
    name="komodo_$(arg komodo_id)_Creative_Camera_link">
    <inertial>
      <origin
        xyz="0.000246466472824558 6.40214461760665E-06 -3.77569804070194E-05"
        rpy="0 0 0" />
      <mass
        value="0.0917411732955106" />
      <inertia
        ixx="9.42830385924344E-05"
        ixy="7.20275321596364E-09"
        ixz="-9.53710985095244E-09"
        iyy="1.31046061468615E-05"
        iyz="2.49172946580444E-11"
        izz="9.18985906934582E-05" />
    </inertial>
    <visual>
      <origin
        xyz="0 0 0"
        rpy="0 0 0" />
      <geometry>
        <mesh
          filename="package://ric_description/komodo/meshes_elevator/Creative_Camera_link.STL" />
      </geometry>
      <material
        name="">
        <color
          rgba="0.2 0.2 0.2 1" />
      </material>
    </visual>
    <collision>
      <origin
        xyz="0 0 0"
        rpy="0 0 0" />
      <geometry>
        <mesh
          filename="package://ric_description/komodo/meshes_elevator/Creative_Camera_link.STL" />
      </geometry>
    </collision>
  </link>
  <joint
    name="komodo_$(arg komodo_id)_Creative_Camera_joint"
    type="fixed">
    <origin
      xyz="0.0260250000000002 0 0.0520000000000001"
      rpy="-1.41059322098675E-37 0 -6.20247191139794E-16" />
    <parent
      link="komodo_$(arg komodo_id)_wrist_link" />
    <child
      link="komodo_$(arg komodo_id)_Creative_Camera_link" />
    <axis
      xyz="0 0 0" />
  </joint>
  <link
    name="komodo_$(arg komodo_id)_Asus_Camera_link">
    <inertial>
      <origin
        xyz="-0.0186787128878999 -0.000250455424978622 -0.00418879037489228"
        rpy="0 0 0" />
      <mass
        value="0.172317738459302" />
      <inertia
        ixx="0.00043258025617677"
        ixy="-5.30549374358253E-07"
        ixz="-4.88064241259027E-07"
        iyy="4.50251290386955E-05"
        iyz="-1.80788928482687E-07"
        izz="0.000422864751433858" />
    </inertial>
    <visual>
      <origin
        xyz="0 0 0"
        rpy="0 0 0" />
      <geometry>
        <mesh
          filename="package://ric_description/komodo/meshes_elevator/Asus_Camera_link.STL" />
      </geometry>
      <material
        name="">
        <color
          rgba="0.1792156862745098 0.1819607843137255 0.1933333333333333 1" />
      </material>
    </visual>
    <collision>
      <origin
        xyz="0 0 0"
        rpy="0 0 0" />
      <geometry>
        <mesh
          filename="package://ric_description/komodo/meshes_elevator/Asus_Camera_link.STL" />
      </geometry>
    </collision>
  </link>
  <joint
    name="komodo_$(arg komodo_id)_Asus_Camera_joint"
    type="fixed">
    <origin
      xyz="0.143457996026181 0 0.696234376944339"
      rpy="0 0 0" />
    <parent
      link="komodo_$(arg komodo_id)_Arm_base_link" />
    <child
      link="komodo_$(arg komodo_id)_Asus_Camera_link" />
    <axis
      xyz="0 0 0" />
  </joint>
  <link
    name="komodo_$(arg komodo_id)_Rear_Camera_link">
    <inertial>
      <origin
        xyz="3.63553471786722E-06 0.000213443852905448 -0.00979905092954501"
        rpy="0 0 0" />
      <mass
        value="0.0346828331927957" />
      <inertia
        ixx="6.28790547336403E-06"
        ixy="-2.06834495042828E-09"
        ixz="1.17994816083997E-09"
        iyy="6.08020816375982E-06"
        iyz="3.61787794070637E-08"
        izz="9.95214453956502E-06" />
    </inertial>
    <visual>
      <origin
        xyz="0 0 0"
        rpy="0 0 0" />
      <geometry>
        <mesh
          filename="package://ric_description/komodo/meshes_elevator/Rear_Camera_link.STL" />
      </geometry>
      <material
        name="">
        <color
          rgba="0.1 0.1 0.1 1" />
      </material>
    </visual>
    <collision>
      <origin
        xyz="0 0 0"
        rpy="0 0 0" />
      <geometry>
        <mesh
          filename="package://ric_description/komodo/meshes_elevator/Rear_Camera_link.STL" />
      </geometry>
    </collision>
  </link>
  <joint
    name="komodo_$(arg komodo_id)_Rear_Camera_joint"
    type="fixed">
    <origin
      xyz="0.0329579960261737 0 0.354500000000001"
      rpy="-1.5707963267949 2.92163953848738E-15 1.5707963267949" />
    <parent
      link="komodo_$(arg komodo_id)_Arm_base_link" />
    <child
      link="komodo_$(arg komodo_id)_Rear_Camera_link" />
    <axis
      xyz="0 0 0" />
  </joint>
  <link
    name="komodo_$(arg komodo_id)_Top_Camera_link">
    <inertial>
      <origin
        xyz="4.37351127445876E-06 0.000213430006923504 -0.00979905092954436"
        rpy="0 0 0" />
      <mass
        value="0.0346828331927942" />
      <inertia
        ixx="6.28791729321072E-06"
        ixy="-1.35017062474835E-09"
        ixz="1.30503198120059E-09"
        iyy="6.08019634391293E-06"
        iyz="3.61744833904195E-08"
        izz="9.95214453956468E-06" />
    </inertial>
    <visual>
      <origin
        xyz="0 0 0"
        rpy="0 0 0" />
      <geometry>
        <mesh
          filename="package://ric_description/komodo/meshes_elevator/Top_Camera_link.STL" />
      </geometry>
      <material
        name="">
        <color
          rgba="0.1 0.1 0.1 1" />
      </material>
    </visual>
    <collision>
      <origin
        xyz="0 0 0"
        rpy="0 0 0" />
      <geometry>
        <mesh
          filename="package://ric_description/komodo/meshes_elevator/Top_Camera_link.STL" />
      </geometry>
    </collision>
  </link>
  <joint
    name="komodo_$(arg komodo_id)_Top_Camera_joint"
    type="fixed">
    <origin
      xyz="0.0622079960261761 0.0152829991418538 0.660000000000001"
      rpy="5.38354147863953E-15 1.55701850396119E-12 -1.56733874423455" />
    <parent
      link="komodo_$(arg komodo_id)_Arm_base_link" />
    <child
      link="komodo_$(arg komodo_id)_Top_Camera_link" />
    <axis
      xyz="0 0 0" />
  </joint>
  <link
    name="komodo_$(arg komodo_id)_sensors_unit_link">
    <inertial>
      <origin
        xyz="0.0489076645367545 -0.000360724081928495 0.0483981408156988"
        rpy="0 0 0" />
      <mass
        value="3.10960641386557" />
      <inertia
        ixx="0.0325742442507923"
        ixy="-0.0003205823490616"
        ixz="-0.0117357473230461"
        iyy="0.0999105172237895"
        iyz="1.77344329373949E-05"
        izz="0.122261042056332" />
    </inertial>
    <visual>
      <origin
        xyz="0 0 0"
        rpy="0 0 0" />
      <geometry>
        <mesh
          filename="package://ric_description/komodo/meshes_elevator/sensors_unit_link.STL" />
      </geometry>
      <material
        name="">
        <color
          rgba="0.6509803921568627 0.6537254901960784 0.656078431372549 1" />
      </material>
    </visual>
    <collision>
      <origin
        xyz="0 0 0"
        rpy="0 0 0" />
      <geometry>
        <mesh
          filename="package://ric_description/komodo/meshes_elevator/sensors_unit_link.STL" />
      </geometry>
    </collision>
  </link>
  <joint
    name="komodo_$(arg komodo_id)_sensors_unit_joint"
    type="fixed">
    <origin
      xyz="-0.00199997218323816 0 0.0835000000000002"
      rpy="0 0 0" />
    <parent
      link="komodo_$(arg komodo_id)_base_link" />
    <child
      link="komodo_$(arg komodo_id)_sensors_unit_link" />
    <axis
      xyz="0 0 0" />
  </joint>
</robot>
